Workbook

Sheet Demandeur Princ. - Époux (Moi)
A1: Candidature 1 — Demandeur principal : ÉPOUX (moi) — Togo
A2: Légende : cases JAUNES = à remplir · texte BLEU = prérempli d'après vos indications (à vérifier) · texte VERT sur gris = repris automatiquement d'un autre onglet · cases GRISES = calculées (ne pas modifier). Colonne D = exemple FICTIF de format, à remplacer par vos vraies données. Colonne G : cochez « Oui » une fois la valeur comparée au document officiel.
A3: Complétude (champs obligatoires remplis) | C3: =IFERROR(SUMPRODUCT((E7:E62="Oui")*(C7:C62<>""))/COUNTIF(E7:E62,"Oui"),0) -> 0.31034483
A4: Vérification (champs obligatoires cochés « Oui ») | C4: =IFERROR(SUMPRODUCT((E7:E62="Oui")*(G7:G62="Oui"))/COUNTIF(E7:E62,"Oui"),0) -> 0
A6: Champ officiel (formulaire) | B6: Libellé (FR) | C6: Valeur à saisir | D6: Exemple de format (fictif) | E6: Obligatoire | F6: Consigne / piège à éviter | G6: Vérifié ?
A7: A. IDENTITÉ — exactement comme sur le passeport et l'acte de naissance
A8: Family Name / Last Name | B8: Nom de famille | D8: KOFFI | E8: Oui | F8: Accents, tirets et ordre des noms exactement comme sur le passeport. Si une seule identité : la saisir en Last Name et mettre FNU en First Name (instruction habituelle, à revérifier).
A9: First Name | B9: Prénom (premier prénom) | D9: Mawuli | E9: Oui | F9: Comme sur le passeport.
A10: Middle Name | B10: Autre(s) prénom(s) | D10: Kodjo | E10: Non | F10: Laisser vide s'il n'y en a pas.
A11: Gender (Sex) | B11: Genre | D11: Male | E11: Oui | F11: Menu : Male / Female, comme sur le passeport.
A12: Birth Date — Day | B12: Jour de naissance | D12: 7 | E12: Oui | F12: 1 à 31.
A13: Birth Date — Month | B13: Mois de naissance | D13: 3 | E13: Oui | F13: 1 à 12.
A14: Birth Date — Year | B14: Année de naissance | D14: 1992 | E14: Oui | F14: 4 chiffres. Doit être identique sur toutes les pièces.
A15: City of Birth | B15: Ville de naissance | D15: Lomé | E15: Oui | F15: Comme sur l'acte de naissance.
A16: Country of Birth | B16: Pays de naissance | C16: Togo | D16: Togo | E16: Oui | F16: À confirmer sur l'acte de naissance.
A17: Country of Eligibility for the DV Program | B17: Pays d'éligibilité (chargeability) | C17: Togo | D17: Togo | E17: Oui | F17: Éligible par naissance. À revérifier dans la liste officielle des pays éligibles de la session.
A18: B. ADRESSE POSTALE & CONTACT
A19: In Care Of | B19: À l'attention de (facultatif) | E19: Non
A20: Address Line 1 | B20: Adresse — ligne 1 | D20: 123 Rue des Palmiers | E20: Oui
A21: Address Line 2 | B21: Adresse — ligne 2 | D21: Quartier Adidogomé | E21: Non
A22: City/Town | B22: Ville | C22: Lomé | D22: Lomé | E22: Oui | F22: Ville de résidence actuelle.
A23: District/Country/Province/State | B23: District / Région | D23: Maritime | E23: Oui
A24: Postal Code / Zip Code | B24: Code postal | D24: 00000 | E24: Oui | F24: S'il n'existe pas de code postal, saisir 00000.
A25: Country (mailing address) | B25: Pays (adresse postale) | C25: Togo | D25: Togo | E25: Oui
A26: Country where you live today | B26: Pays de résidence actuel | C26: Togo | D26: Togo | E26: Oui
A27: Phone Number (optional) | B27: Numéro de téléphone | D27: +228 90 00 00 00 | E27: Non | F27: Facultatif sur le formulaire.
A28: E-mail Address | B28: Adresse e-mail | D28: prenom.nom@exemple.com | E28: Oui | F28: Adresse personnelle que VOUS contrôlez, avec mot de passe fort et double authentification. Conseillé : une adresse distincte par candidature, chaque principal accédant à sa propre confirmation. Ne jamais la confier à un agent.
A29: C. ÉTUDES & ÉTAT CIVIL
A30: Highest level of education | B30: Niveau d'études le plus élevé | C30: University degree | D30: University degree | E30: Oui | F30: Prérempli d'après votre Licence (Université de Lomé) : à vérifier sur le diplôme. Le formulaire demande le niveau d'études, pas le métier.
A31: Marital status | B31: Statut matrimonial | C31: Married and my spouse is NOT a U.S. citizen or U.S. LPR | D31: Married and my spouse is NOT a U.S. citizen or U.S. LPR | E31: Oui | F31: Même réponse dans les deux candidatures.
A32: Number of children | B32: Nombre d'enfants | C32: 1 | D32: 1 | E32: Oui | F32: Tous les enfants célibataires de moins de 21 ans (biologiques, adoptés, beaux-enfants) — identique dans les deux candidatures.
A33: D. PASSEPORT (obligatoire pour le demandeur principal dès DV-2027)
A34: Passport number | B34: Passeport — numéro | D34: AB1234567 | E34: Oui | F34: Numéro de série exactement comme imprimé.
A35: Passport issuing country | B35: Passeport — pays de délivrance | C35: Togo | D35: Togo | E35: Oui
A36: Passport expiration date | B36: Passeport — date d'expiration | D36: 15/06/2031 | E36: Oui | F36: Doit être valide et non expiré.
A37: Auto-check: passport validity | B37: Contrôle auto — validité du passeport | C37: =IF(C36="","",IF(C36>'Checklist Docs & Validation'!$D$4,"OK","À RENOUVELER (expire avant la date repère)")) | E37: Oui
A38: Passport scan file (JPEG) | B38: Passeport — fichier scan (JPEG) | D38: passeport_epoux.jpg | E38: Oui | F38: Scan JPEG de la page biographique ET de la page de signature.
A39: E. PHOTO DU DEMANDEUR PRINCIPAL
A40: Photo file name | B40: Photo — nom du fichier | D40: epoux_600x600.jpg | E40: Oui | F40: JPEG, couleur, fond clair uni, de face, sans lunettes ni couvre-chef, sans filtre ni retouche, pas de selfie. Faire faire la photo par un professionnel connaissant le format DV.
A41: Photo dimensions (px) | B41: Photo — dimensions (px) | D41: 600x600 | E41: Oui | F41: Saisir exactement 600x600 (carré).
...

Sheet Demandeur Princ. - Épouse
A1: Candidature 2 — Demandeur principal : ÉPOUSE
A2: Légende : cases JAUNES = à remplir · texte BLEU = prérempli d'après vos indications (à vérifier) · texte VERT sur gris = repris automatiquement d'un autre onglet · cases GRISES = calculées (ne pas modifier). Colonne D = exemple FICTIF de format, à remplacer par vos vraies données. Colonne G : cochez « Oui » une fois la valeur comparée au document officiel.
A3: Complétude (champs obligatoires remplis) | C3: =IFERROR(SUMPRODUCT((E7:E62="Oui")*(C7:C62<>""))/COUNTIF(E7:E62,"Oui"),0) -> 0.068965517
A4: Vérification (champs obligatoires cochés « Oui ») | C4: =IFERROR(SUMPRODUCT((E7:E62="Oui")*(G7:G62="Oui"))/COUNTIF(E7:E62,"Oui"),0) -> 0
A6: Champ officiel (formulaire) | B6: Libellé (FR) | C6: Valeur à saisir | D6: Exemple de format (fictif) | E6: Obligatoire | F6: Consigne / piège à éviter | G6: Vérifié ?
A7: A. IDENTITÉ — exactement comme sur le passeport et l'acte de naissance
A8: Family Name / Last Name | B8: Nom de famille | D8: KOFFI | E8: Oui | F8: Accents, tirets et ordre des noms exactement comme sur le passeport. Si une seule identité : la saisir en Last Name et mettre FNU en First Name (instruction habituelle, à revérifier).
A9: First Name | B9: Prénom (premier prénom) | D9: Mawuli | E9: Oui | F9: Comme sur le passeport.
A10: Middle Name | B10: Autre(s) prénom(s) | D10: Kodjo | E10: Non | F10: Laisser vide s'il n'y en a pas.
A11: Gender (Sex) | B11: Genre | D11: Male | E11: Oui | F11: Menu : Male / Female, comme sur le passeport.
A12: Birth Date — Day | B12: Jour de naissance | D12: 7 | E12: Oui | F12: 1 à 31.
A13: Birth Date — Month | B13: Mois de naissance | D13: 3 | E13: Oui | F13: 1 à 12.
A14: Birth Date — Year | B14: Année de naissance | D14: 1992 | E14: Oui | F14: 4 chiffres. Doit être identique sur toutes les pièces.
A15: City of Birth | B15: Ville de naissance | D15: Lomé | E15: Oui | F15: Comme sur l'acte de naissance.
A16: Country of Birth | B16: Pays de naissance | D16: Togo | E16: Oui | F16: À renseigner d'après son acte de naissance (non précisé dans votre demande).
A17: Country of Eligibility for the DV Program | B17: Pays d'éligibilité (chargeability) | D17: Togo | E17: Oui | F17: Son pays de naissance si éligible. À défaut, le principe de chargeability permet parfois de retenir le pays de naissance du conjoint : à confirmer dans les instructions officielles de la session.
A18: B. ADRESSE POSTALE & CONTACT
A19: In Care Of | B19: À l'attention de (facultatif) | E19: Non
A20: Address Line 1 | B20: Adresse — ligne 1 | D20: 123 Rue des Palmiers | E20: Oui
A21: Address Line 2 | B21: Adresse — ligne 2 | D21: Quartier Adidogomé | E21: Non
A22: City/Town | B22: Ville | D22: Lomé | E22: Oui | F22: Ville de résidence actuelle.
A23: District/Country/Province/State | B23: District / Région | D23: Maritime | E23: Oui
A24: Postal Code / Zip Code | B24: Code postal | D24: 00000 | E24: Oui | F24: S'il n'existe pas de code postal, saisir 00000.
A25: Country (mailing address) | B25: Pays (adresse postale) | D25: Togo | E25: Oui
A26: Country where you live today | B26: Pays de résidence actuel | D26: Togo | E26: Oui
A27: Phone Number (optional) | B27: Numéro de téléphone | D27: +228 90 00 00 00 | E27: Non | F27: Facultatif sur le formulaire.
A28: E-mail Address | B28: Adresse e-mail | D28: prenom.nom@exemple.com | E28: Oui | F28: Adresse personnelle que VOUS contrôlez, avec mot de passe fort et double authentification. Conseillé : une adresse distincte par candidature, chaque principal accédant à sa propre confirmation. Ne jamais la confier à un agent.
A29: C. ÉTUDES & ÉTAT CIVIL
A30: Highest level of education | B30: Niveau d'études le plus élevé | D30: University degree | E30: Oui | F30: Elle est principale sur la candidature 2 : elle doit remplir seule la condition (diplôme de fin d'études secondaires, ou 2 ans d'expérience sur les 5 dernières années dans un métier éligible O*NET).
A31: Marital status | B31: Statut matrimonial | C31: Married and my spouse is NOT a U.S. citizen or U.S. LPR | D31: Married and my spouse is NOT a U.S. citizen or U.S. LPR | E31: Oui | F31: Même réponse dans les deux candidatures.
A32: Number of children | B32: Nombre d'enfants | C32: 1 | D32: 1 | E32: Oui | F32: Tous les enfants célibataires de moins de 21 ans (biologiques, adoptés, beaux-enfants) — identique dans les deux candidatures.
A33: D. PASSEPORT (obligatoire pour le demandeur principal dès DV-2027)
A34: Passport number | B34: Passeport — numéro | D34: AB1234567 | E34: Oui | F34: Numéro de série exactement comme imprimé.
A35: Passport issuing country | B35: Passeport — pays de délivrance | D35: Togo | E35: Oui
A36: Passport expiration date | B36: Passeport — date d'expiration | D36: 15/06/2031 | E36: Oui | F36: Doit être valide et non expiré.
A37: Auto-check: passport validity | B37: Contrôle auto — validité du passeport | C37: =IF(C36="","",IF(C36>'Checklist Docs & Validation'!$D$4,"OK","À RENOUVELER (expire avant la date repère)")) | E37: Oui
A38: Passport scan file (JPEG) | B38: Passeport — fichier scan (JPEG) | D38: passeport_epoux.jpg | E38: Oui | F38: Scan JPEG de la page biographique ET de la page de signature.
A39: E. PHOTO DU DEMANDEUR PRINCIPAL
A40: Photo file name | B40: Photo — nom du fichier | D40: epoux_600x600.jpg | E40: Oui | F40: JPEG, couleur, fond clair uni, de face, sans lunettes ni couvre-chef, sans filtre ni retouche, pas de selfie. Faire faire la photo par un professionnel connaissant le format DV.
A41: Photo dimensions (px) | B41: Photo — dimensions (px) | D41: 600x600 | E41: Oui | F41: Saisir exactement 600x600 (carré).
...

Sheet Enfant (Fils)
A1: Enfant (fils) — déclaré dans les DEUX candidatures
A2: Légende : cases JAUNES = à remplir · texte BLEU = prérempli d'après vos indications (à vérifier) · texte VERT sur gris = repris automatiquement d'un autre onglet · cases GRISES = calculées (ne pas modifier). Colonne D = exemple FICTIF de format, à remplacer par vos vraies données. Colonne G : cochez « Oui » une fois la valeur comparée au document officiel.
A3: Complétude (champs obligatoires remplis) | C3: =IFERROR(SUMPRODUCT((E7:E32="Oui")*(C7:C32<>""))/COUNTIF(E7:E32,"Oui"),0) -> 0.058823529
A4: Vérification (champs obligatoires cochés « Oui ») | C4: =IFERROR(SUMPRODUCT((E7:E32="Oui")*(G7:G32="Oui"))/COUNTIF(E7:E32,"Oui"),0) -> 0
A6: Champ officiel (formulaire) | B6: Libellé (FR) | C6: Valeur à saisir | D6: Exemple de format (fictif) | E6: Obligatoire | F6: Consigne / piège à éviter | G6: Vérifié ?
A7: A. IDENTITÉ — exactement comme sur l'acte de naissance
A8: Family Name / Last Name | B8: Nom de famille | D8: KOFFI | E8: Oui | F8: Comme sur l'acte de naissance (et le passeport s'il en a un).
A9: First Name | B9: Prénom | D9: Komla | E9: Oui
A10: Middle Name | B10: Autre(s) prénom(s) | E10: Non
A11: Gender (Sex) | B11: Genre | D11: Male | E11: Oui | F11: Fils : Male (menu déroulant).
A12: Birth Date — Day | B12: Jour de naissance | D12: 12 | E12: Oui
A13: Birth Date — Month | B13: Mois de naissance | D13: 8 | E13: Oui
A14: Birth Date — Year | B14: Année de naissance | D14: 2025 | E14: Oui
A15: City of Birth | B15: Ville de naissance | D15: Lomé | E15: Oui
A16: Country of Birth | B16: Pays de naissance | D16: Togo | E16: Oui | F16: D'après l'acte de naissance.
A17: Relationship to principal | B17: Lien avec les parents | D17: Biological child | E17: Oui | F17: Même enfant déclaré à l'identique dans les DEUX candidatures.
A18: B. ÉTAT CIVIL & ÂGE
A19: Child marital status | B19: Statut matrimonial de l'enfant | C19: Unmarried | D19: Unmarried | E19: Oui | F19: Doit être célibataire et avoir moins de 21 ans à la date de l'inscription.
A20: Planned entry date | B20: Date prévue de l'inscription | D20: 05/11/2026 | E20: Non | F20: À saisir dès que la date est connue : sert au contrôle d'âge ci-dessous.
A21: Auto-check: age under 21 | B21: Contrôle auto — moins de 21 ans | C21: =IF(OR(C12="",C13="",C14="",C20=""),"",IF(DATE(C14+21,C13,C12)>C20,"OK (moins de 21 ans)","ALERTE : 21 ans révolus")) | E21: Oui
A22: C. PASSEPORT (facultatif : l'exigence d'inscription porte sur le demandeur principal)
A23: Passport number | B23: Passeport — numéro | D23: AB7654321 | E23: Non
A24: Passport issuing country | B24: Passeport — pays de délivrance | D24: Togo | E24: Non
A25: Passport expiration date | B25: Passeport — date d'expiration | D25: 15/06/2030 | E25: Non
A26: Auto-check: passport validity | B26: Contrôle auto — validité du passeport | C26: =IF(C25="","",IF(C25>'Checklist Docs & Validation'!$D$4,"OK","À RENOUVELER (expire avant la date repère)")) | E26: Oui
A27: D. PHOTO DE L'ENFANT
A28: Photo file name | B28: Photo — nom du fichier | D28: epoux_600x600.jpg | E28: Oui | F28: JPEG, couleur, fond clair uni, de face, sans lunettes ni couvre-chef, sans filtre ni retouche, pas de selfie. Faire faire la photo par un professionnel connaissant le format DV.
A29: Photo dimensions (px) | B29: Photo — dimensions (px) | D29: 600x600 | E29: Oui | F29: Saisir exactement 600x600 (carré).
A30: Photo size (KB) | B30: Photo — poids (Ko) | D30: 180 | E30: Oui | F30: Maximum 240 Ko.
A31: Photo date taken | B31: Photo — date de prise de vue | D31: 01/10/2026 | E31: Oui | F31: Prise de vue de moins de 6 mois avant l'inscription (contrôle ≈ 183 jours par rapport à aujourd'hui).
A32: Auto-check: photo | B32: Contrôle auto — photo | C32: =IF(OR(C29="",C30="",C31=""),"",IF(AND(C29="600x600",C30<=240,TODAY()-C31<=183,TODAY()>=C31),"OK","À CORRIGER")) | E32: Oui

Sheet Checklist Docs & Validation
A1: Checklist Documents & Validation — DV Lottery (2 candidatures séparées)
A2: Ce classeur est un outil de préparation, pas une source officielle : les dates, la liste des pays éligibles et les instructions de la session (travel.state.gov, dvprogram.state.gov) priment. Menu « Statut » : À faire / En cours / OK / N/A. Case jaune = à modifier.
C4: Date repère de validité des passeports | D4: 46660 | E4: Hypothèse de travail : 30/09/2027 = fin de l'année fiscale DV-2027, date limite légale de délivrance des visas de cette session. Marge de sécurité recommandée, PAS une exigence officielle ; modifiable.
C6: Complétude — onglet Époux | D6: ='Demandeur Princ. - Époux (Moi)'!C3 -> 0.31034483
C7: Complétude — onglet Épouse | D7: ='Demandeur Princ. - Épouse'!C3 -> 0.068965517
C8: Complétude — onglet Enfant | D8: ='Enfant (Fils)'!C3 -> 0.058823529
C9: Avancement de la checklist (éléments « OK ») | D9: =IFERROR(COUNTIF(F13:F42,"OK")/(COUNTA(F13:F42)-COUNTIF(F13:F42,"N/A")),0) -> 0
A11: N° | B11: Phase | C11: Élément à contrôler | D11: Concerne | E11: Détail / règle | F11: Statut | G11: Preuve / date | H11: Remarques
A12: PHASE 1 — AVANT L'OUVERTURE
A13: 1 | B13: Phase 1 | C13: Annonce officielle lue : dates, durée (30 jours minimum selon l'ordonnance en cours), liste des pays éligibles, instructions | D13: Les deux | E13: Sources : travel.state.gov et dvprogram.state.gov uniquement. Ne pas se fier aux dates des sites tiers. | F13: À faire
A14: 2 | B14: Phase 1 | C14: Togo présent dans la liste officielle des pays éligibles de la session | D14: Les deux | E14: À revérifier à chaque session : la liste est publiée avec les instructions. | F14: À faire
A15: 3 | B15: Phase 1 | C15: Restrictions de visa ou de voyage en vigueur vérifiées pour les ressortissants du Togo (au stade visa) | D15: Les deux | E15: Les politiques ont changé plusieurs fois en 2025-2026 : revérifier au moment de l'inscription et après sélection. | F15: À faire
A16: 4 | B16: Phase 1 | C16: Passeport de l'époux valide et non expiré, au-delà de la date repère | D16: Époux | E16: Voir D4 ci-dessus et le contrôle auto de l'onglet Époux. | F16: À faire
A17: 5 | B17: Phase 1 | C17: Passeport de l'épouse valide et non expiré, au-delà de la date repère | D17: Épouse | E17: Elle est principale sur la candidature 2 : son passeport est obligatoire. | F17: À faire
A18: 6 | B18: Phase 1 | C18: Scan JPEG de la page biographique et de la page de signature — époux | D18: Époux | E18: Lisible, sans reflet, sans retouche. | F18: À faire
A19: 7 | B19: Phase 1 | C19: Scan JPEG de la page biographique et de la page de signature — épouse | D19: Épouse | E19: Idem. | F19: À faire
A20: 8 | B20: Phase 1 | C20: Noms et prénoms saisis = passeport (ordre, accents, tirets) — époux et épouse | D20: Les deux | E20: Comparer caractère par caractère. | F20: À faire
A21: 9 | B21: Phase 1 | C21: Condition d'études ou d'expérience remplie par l'époux (diplôme de fin d'études secondaires ou équivalent) | D21: Époux | E21: Conserver le diplôme/relevé : il sera exigé si vous êtes sélectionné. | F21: À faire
A22: 10 | B22: Phase 1 | C22: Condition d'études ou d'expérience remplie par l'épouse, seule | D22: Épouse | E22: Indispensable pour que la candidature 2 soit exploitable : diplôme de fin d'études secondaires, ou 2 ans d'expérience sur les 5 dernières années dans un métier éligible (O*NET). | F22: À faire
A23: 11 | B23: Phase 1 | C23: Pays de naissance et pays d'éligibilité confirmés par les actes de naissance (3 personnes) | D23: Les trois | E23: Pays d'éligibilité de l'épouse à déterminer selon les règles de chargeability. | F23: À faire
A24: 12 | B24: Phase 1 | C24: Dates de naissance identiques sur actes, passeports et formulaires (3 personnes) | D24: Les trois | E24: Une incohérence se paie au consulat. | F24: À faire
... A29: 17 | B29: Phase 1 | C29: Moyen de paiement prêt pour 1 $ par candidature (2 paiements) | D29: Les deux | E29: Frais non remboursables, payés en ligne lors de la soumission. | F29: À faire
A30: PHASE 2 — PENDANT L'INSCRIPTION
A31: 18 | B31: Phase 2 | C31: Inscription uniquement sur dvprogram.state.gov | D31: Les deux | E31: Aucun intermédiaire, aucun site « officiel » alternatif. | F31: À faire
A32: 19 | B32: Phase 2 | C32: Relecture complète de chaque champ avant de valider (comparer à cet onglet) | D32: Les deux | E32: Après soumission, les données ne se corrigent pas. | F32: À faire
A33: 20 | B33: Phase 2 | C33: Candidature 1 soumise (époux principal) — numéro de confirmation noté | D33: Époux | E33: Notez-le dans l'onglet Comparatif. | F33: À faire
A34: 21 | B34: Phase 2 | C34: Candidature 2 soumise (épouse principale) — numéro de confirmation noté | D34: Épouse | E34: Idem. | F34: À faire
A35: 22 | B35: Phase 2 | C35: Reçus des paiements de 1 $ archivés (2) | D35: Les deux | E35: PDF ou capture d'écran. | F35: À faire
A36: 23 | B36: Phase 2 | C36: Pages de confirmation enregistrées en PDF + numéros de confirmation et dates de naissance sauvegardés en 2 endroits hors ligne | D36: Les deux | E36: Indispensable pour consulter le résultat. | F36: À faire
A37: 24 | B37: Phase 2 | C37: Soumission faite tôt dans la période d'inscription, pas le dernier jour | D37: Les deux | E37: Évite les saturations de dernière minute. | F37: À faire
A38: PHASE 3 — APRÈS LES RÉSULTATS
A39: 25 | B39: Phase 3 | C39: Résultat consulté uniquement via Entrant Status Check sur dvprogram.state.gov | D39: Les deux | E39: Aucun courriel officiel n'annonce une victoire ; ignorer tout message en ce sens. | F39: À faire
A40: 26 | B40: Phase 3 | C40: Si sélectionné : DS-260 complété pour toute la famille avec les mêmes données que l'inscription | D40: Les trois | E40: Fixer un calendrier serré : la date limite légale est le 30 septembre de l'année fiscale. | F40: À faire
A41: 27 | B41: Phase 3 | C41: Documents civils réunis : actes de naissance (3), acte de mariage, passeports, diplôme, extraits de casier judiciaire, photos, examen médical | D41: Les trois | E41: Liste exacte à confirmer sur le site du consulat compétent. | F41: À faire
A42: 28 | B42: Phase 3 | C42: Si les deux candidatures sont sélectionnées : décider avec le consulat de la procédure unique à mener pour la famille | D42: Les deux | E42: Demander confirmation écrite de la marche à suivre avant d'engager des frais. | F42: À faire

Sheet Comparatif 2 Candidatures
A1: Comparatif des 2 candidatures — stratégie « double chance » légale
A2: Tout est calculé à partir des onglets Époux, Épouse et Enfant : ne rien saisir dans les cellules grises/vertes. Cases jaunes = suivi à remplir au fil de l'eau. Rappel : chaque personne n'a qu'UNE candidature principale ; chaque candidature déclare toute la famille. Deux candidatures doublent les chances de la famille, pas celles de chaque personne.
A4: Bloc | B4: Élément | C4: Candidature 1 — Époux principal (+ Épouse + Fils) | D4: Candidature 2 — Épouse principale (+ Époux + Fils) | E4: Remarque
A5: 1. SYNTHÈSE DES DEUX CANDIDATURES
A6: Composition | B6: Demandeur principal | C6: =TRIM('Demandeur Princ. - Époux (Moi)'!C8&" "&'Demandeur Princ. - Époux (Moi)'!C9&" "&'Demandeur Princ. - Époux (Moi)'!C10) | D6: =TRIM('Demandeur Princ. - Épouse'!C8&" "&'Demandeur Princ. - Épouse'!C9&" "&'Demandeur Princ. - Épouse'!C10) | E6: Deux personnes différentes, une candidature principale chacune.
A7: Composition | B7: Conjoint déclaré | C7: =TRIM('Demandeur Princ. - Épouse'!C8&" "&'Demandeur Princ. - Épouse'!C9&" "&'Demandeur Princ. - Épouse'!C10) | D7: =TRIM('Demandeur Princ. - Époux (Moi)'!C8&" "&'Demandeur Princ. - Époux (Moi)'!C9&" "&'Demandeur Princ. - Époux (Moi)'!C10) | E7: Chaque principal déclare l'autre.
A8: Composition | B8: Enfant déclaré (fils) | C8: =TRIM('Enfant (Fils)'!C8&" "&'Enfant (Fils)'!C9&" "&'Enfant (Fils)'!C10) | D8: =TRIM('Enfant (Fils)'!C8&" "&'Enfant (Fils)'!C9&" "&'Enfant (Fils)'!C10) | E8: Le même enfant dans les deux candidatures.
A9: Composition | B9: Nombre d'enfants déclaré | C9: =IF('Demandeur Princ. - Époux (Moi)'!C32="","",'Demandeur Princ. - Époux (Moi)'!C32) -> 1 | D9: =IF('Demandeur Princ. - Épouse'!C32="","",'Demandeur Princ. - Épouse'!C32) -> 1 | E9: Doit être identique.
A10: Éligibilité | B10: Pays d'éligibilité utilisé | C10: =IF('Demandeur Princ. - Époux (Moi)'!C17="","",'Demandeur Princ. - Époux (Moi)'!C17) -> Togo | D10: =IF('Demandeur Princ. - Épouse'!C17="","",'Demandeur Princ. - Épouse'!C17) | E10: Vérifier dans la liste officielle de la session.
A11: Contact | B11: E-mail du demandeur principal | C11: =IF('Demandeur Princ. - Époux (Moi)'!C28="","",'Demandeur Princ. - Époux (Moi)'!C28) | D11: =IF('Demandeur Princ. - Épouse'!C28="","",'Demandeur Princ. - Épouse'!C28) | E11: Une adresse par candidature recommandée.
A12: Passeport | B12: Date d'expiration du passeport (principal) | C12: =IF('Demandeur Princ. - Époux (Moi)'!C36="","",'Demandeur Princ. - Époux (Moi)'!C36) | D12: =IF('Demandeur Princ. - Épouse'!C36="","",'Demandeur Princ. - Épouse'!C36)
A13: Passeport | B13: Contrôle validité du passeport | C13: =IF('Demandeur Princ. - Époux (Moi)'!C37="","",'Demandeur Princ. - Époux (Moi)'!C37) | D13: =IF('Demandeur Princ. - Épouse'!C37="","",'Demandeur Princ. - Épouse'!C37) | E13: Par rapport à la date repère de l'onglet Checklist.
A14: Avancement | B14: Complétude — données du principal | C14: ='Demandeur Princ. - Époux (Moi)'!C3 -> 0.31034483 | D14: ='Demandeur Princ. - Épouse'!C3 -> 0.068965517 | E14: Part des champs obligatoires remplis.
A15: Avancement | B15: Complétude — données du conjoint déclaré | C15: ='Demandeur Princ. - Épouse'!C3 -> 0.068965517 | D15: ='Demandeur Princ. - Époux (Moi)'!C3 -> 0.31034483
A16: Avancement | B16: Complétude — données de l'enfant | C16: ='Enfant (Fils)'!C3 -> 0.058823529 | D16: ='Enfant (Fils)'!C3 -> 0.058823529
A17: 2. SUIVI DE L'INSCRIPTION (à remplir)
A18: Soumission | B18: Date et heure de soumission
A19: Soumission | B19: Numéro de confirmation | E19: À conserver hors ligne, avec la date de naissance du principal.
A20: Soumission | B20: Frais de 1 $ payés ? | E20: Reçu archivé.
A21: Soumission | B21: PDF de confirmation archivé ?
A22: Résultat | B22: Résultat (Entrant Status Check) | C22: Pas encore vérifié | D22: Pas encore vérifié | E22: Uniquement via dvprogram.state.gov.
A23: 3. CONTRÔLES DE COHÉRENCE ENTRE LES DEUX CANDIDATURES
A24: Contrôle | B24: Deux demandeurs principaux distincts | C24: =IF(OR(TRIM(C6)="",TRIM(D6)=""),"",IF(UPPER(TRIM(C6))<>UPPER(TRIM(D6)),"OK","ERREUR : même personne")) | E24: Évite un doublon de la même personne.
A25: Contrôle | B25: Même statut matrimonial dans les deux | C25: =IF(OR('Demandeur Princ. - Époux (Moi)'!C31="",'Demandeur Princ. - Épouse'!C31=""),"",IF('Demandeur Princ. - Époux (Moi)'!C31='Demandeur Princ. - Épouse'!C31,"OK","INCOHÉRENT")) -> OK
A26: Contrôle | B26: Même nombre d'enfants dans les deux | C26: =IF(OR('Demandeur Princ. - Époux (Moi)'!C32="",'Demandeur Princ. - Épouse'!C32=""),"",IF('Demandeur Princ. - Époux (Moi)'!C32='Demandeur Princ. - Épouse'!C32,"OK","INCOHÉRENT")) -> OK
A27: Contrôle | B27: Pays d'éligibilité renseigné pour les 2 principaux | C27: =IF(AND('Demandeur Princ. - Époux (Moi)'!C17<>"",'Demandeur Princ. - Épouse'!C17<>""),"OK","À renseigner") -> À renseigner
A28: Contrôle | B28: Passeports des 2 principaux valides au-delà de la date repère | C28: =IF(OR('Demandeur Princ. - Époux (Moi)'!C37="",'Demandeur Princ. - Épouse'!C37=""),"",IF(AND('Demandeur Princ. - Époux (Moi)'!C37="OK",'Demandeur Princ. - Épouse'!C37="OK"),"OK","À corriger"))
A29: Contrôle | B29: Photos conformes (époux, épouse, fils) | C29: =IF(('Demandeur Princ. - Époux (Moi)'!C44="OK")+('Demandeur Princ. - Épouse'!C44="OK")+('Enfant (Fils)'!C32="OK")=3,"OK","À vérifier") -> À vérifier
A30: 4. DONNÉES À SAISIR — COPIER-COLLER (reprises des onglets)
A31: Principal | B31: Family Name | C31: =IF('Demandeur Princ. - Époux (Moi)'!C8="","",'Demandeur Princ. - Époux (Moi)'!C8) | D31: =IF('Demandeur Princ. - Épouse'!C8="","",'Demandeur Princ. - Épouse'!C8)
A32: Principal | B32: First Name | C32: =IF('Demandeur Princ. - Époux (Moi)'!C9="","",'Demandeur Princ. - Époux (Moi)'!C9) | D32: =IF('Demandeur Princ. - Épouse'!C9="","",'Demandeur Princ. - Épouse'!C9)
A33: Principal | B33: Middle Name | C33: =IF('Demandeur Princ. - Époux (Moi)'!C10="","",'Demandeur Princ. - Époux (Moi)'!C10) | D33: =IF('Demandeur Princ. - Épouse'!C10="","",'Demandeur Princ. - Épouse'!C10)
A34: Principal | B34: Gender | C34: =IF('Demandeur Princ. - Époux (Moi)'!C11="","",'Demandeur Princ. - Époux (Moi)'!C11) | D34: =IF('Demandeur Princ. - Épouse'!C11="","",'Demandeur Princ. - Épouse'!C11)
A35: Principal | B35: Birth date (JJ/MM/AAAA) | C35: =IF(OR('Demandeur Princ. - Époux (Moi)'!C12="",'Demandeur Princ. - Époux (Moi)'!C13="",'Demandeur Princ. - Époux (Moi)'!C14=""),"",TEXT('Demandeur Princ. - Époux (Moi)'!C12,"00")&"/"&TEXT('Demandeur Princ. - Époux (Moi)'!C13,"00")&"/"&'Demandeur Princ. - Époux (Moi)'!C14) | D35: =IF(OR('Demandeur Princ. - Épouse'!C12="",'Demandeur Princ. - Épouse'!C13="",'Demandeur Princ. - Épouse'!C14=""),"",TEXT('Demandeur Princ. - Épouse'!C12,"00")&"/"&TEXT('Demandeur Princ. - Épouse'!C13,"00")&"/"&'Demandeur Princ. - Épouse'!C14)
A36: Principal | B36: City of birth | C36: =IF('Demandeur Princ. - Époux (Moi)'!C15="","",'Demandeur Princ. - Époux (Moi)'!C15) | D36: =IF('Demandeur Princ. - Épouse'!C15="","",'Demandeur Princ. - Épouse'!C15)
A37: Principal | B37: Country of birth | C37: =IF('Demandeur Princ. - Époux (Moi)'!C16="","",'Demandeur Princ. - Époux (Moi)'!C16) -> Togo | D37: =IF('Demandeur Princ. - Épouse'!C16="","",'Demandeur Princ. - Épouse'!C16)
A38: Principal | B38: Country of eligibility | C38: =IF('Demandeur Princ. - Époux (Moi)'!C17="","",'Demandeur Princ. - Époux (Moi)'!C17) -> Togo | D38: =IF('Demandeur Princ. - Épouse'!C17="","",'Demandeur Princ. - Épouse'!C17)
A39: Principal | B39: Address line 1 | C39: =IF('Demandeur Princ. - Époux (Moi)'!C20="","",'Demandeur Princ. - Époux (Moi)'!C20) | D39: =IF('Demandeur Princ. - Épouse'!C20="","",'Demandeur Princ. - Épouse'!C20)
A40: Principal | B40: Address line 2 | C40: =IF('Demandeur Princ. - Époux (Moi)'!C21="","",'Demandeur Princ. - Époux (Moi)'!C21) | D40: =IF('Demandeur Princ. - Épouse'!C21="","",'Demandeur Princ. - Épouse'!C21)
A41: Principal | B41: City | C41: =IF('Demandeur Princ. - Époux (Moi)'!C22="","",'Demandeur Princ. - Époux (Moi)'!C22) -> Lomé | D41: =IF('Demandeur Princ. - Épouse'!C22="","",'Demandeur Princ. - Épouse'!C22)
...

Sheet Listes
A1: Niveau d'études (liste du formulaire) | B1: Statut matrimonial | C1: Lien avec l'enfant | D1: Genre | E1: Résultat
A2: Primary school only | B2: Unmarried | C2: Biological child | D2: Male | E2: Pas encore vérifié
A3: Some high school, no diploma | B3: Married and my spouse is NOT a U.S. citizen or U.S. LPR | C3: Adopted child | D3: Female | E3: Sélectionné
A4: High school diploma | B4: Married and my spouse IS a U.S. citizen or U.S. LPR | C4: Stepchild | E4: Non sélectionné
A5: Vocational school | B5: Divorced
A6: Some university courses | B6: Widowed
A7: University degree | B7: Legally Separated
A8: Some graduate level courses
A9: Master's degree
A10: Some doctoral level courses
A11: Doctorate degree
A14: Listes servant aux menus déroulants. Libellés en anglais = ceux du formulaire officiel (à revérifier à l'ouverture de la session).
